Workbook

Sheet Master Products
A1: PRODUCTS MASTER SHEET — v1 (Fresh Build)
A2: Replaces old TGG master catalogue — zero products carried over. Blue cells = edit freely (costs, prices, MOQ). Black = formulas. Green = linked from Crafted sheet.
A3: Example row provided in each category — adjust real costs after vendor quotes.
A5: SKU | B5: Product | C5: Category | D5: Source | E5: Unit Cost (₹) | F5: Selling Price (₹) | G5: Margin % | H5: MOQ | I5: Lead (days) | J5: Best For | K5: Notes
A6: CRAFTED IN-HOUSE
A7: CRF-001 | B7: Velvet-Lined Wooden Keepsake Tray (Small) | C7: Crafted In-House | D7: In-house | E7: ='Crafted In-House'!H7 -> 383.83333 | F7: 749 | G7: =IF(F7=0,0,(F7-E7)/F7) -> 0.48753894 | H7: 1 | I7: 3 | J7: CXO gifting, Finance | K7: Signature hero craft
A8: CRF-002 | B8: Velvet-Lined Wooden Keepsake Tray (Large) | C8: Crafted In-House | D8: In-house | E8: ='Crafted In-House'!H8 -> 583.33333 | F8: 1199 | G8: =IF(F8=0,0,(F8-E8)/F8) -> 0.51348346 | H8: 1 | I8: 3 | J8: CXO / investor boxes | K8: Engravable lid option
A9: CRF-003 | B9: Hand-Poured Soy Candle 120g (Custom Scent) | C9: Crafted In-House | D9: In-house | E9: ='Crafted In-House'!H9 -> 192 | F9: 399 | G9: =IF(F9=0,0,(F9-E9)/F9) -> 0.51879699 | H9: 1 | I9: 3 | J9: All industries | K9: Brand-colour wax option
A10: CRF-004 | B10: Hand-Poured Soy Candle 220g (Amber Jar) | C10: Crafted In-House | D10: In-house | E10: ='Crafted In-House'!H10 -> 266.66667 | F10: 599 | G10: =IF(F10=0,0,(F10-E10)/F10) -> 0.55481358 | H10: 1 | I10: 3 | J10: Premium tiers | K10: Custom label
A11: CRF-005 | B11: Resin Coaster Set of 2 (Brand Colours) | C11: Crafted In-House | D11: In-house | E11: ='Crafted In-House'!H11 -> 228 | F11: 349 | G11: =IF(F11=0,0,(F11-E11)/F11) -> 0.34670487 | H11: 1 | I11: 3 | J11: Tech, Marketing | K11: Logo inlay possible
A12: CRF-006 | B12: Hand-Lettered Note Card + Wax Seal | C12: Crafted In-House | D12: In-house | E12: ='Crafted In-House'!H12 -> 56.333333 | F12: 79 | G12: =IF(F12=0,0,(F12-E12)/F12) -> 0.28691983 | H12: 1 | I12: 3 | J12: Every box | K12: Your handwriting = moat
A13: CRF-007 | B13: Dried-Flower Mini Frame | C13: Crafted In-House | D13: In-house | E13: ='Crafted In-House'!H13 -> 194.16667 | F13: 329 | G13: =IF(F13=0,0,(F13-E13)/F13) -> 0.40982776 | H13: 1 | I13: 3 | J13: HR milestones, EdTech | K13: Lightweight, ships flat
A14: CRF-008 | B14: Potpourri Sachet in Block-Print Pouch | C14: Crafted In-House | D14: In-house | E14: ='Crafted In-House'!H14 -> 89.666667 | F14: 149 | G14: =IF(F14=0,0,(F14-E14)/F14) -> 0.39821029 | H14: 1 | I14: 3 | J14: Filler / aroma layer
A15: CRF-009 | B15: Hand-Tied Fabric Gift Wrap (Furoshiki Style) | C15: Crafted In-House | D15: In-house | E15: ='Crafted In-House'!H15 -> 105 | F15: 199 | G15: =IF(F15=0,0,(F15-E15)/F15) -> 0.47236181 | H15: 1 | I15: 3 | J15: Premium wrap upgrade | K15: Reusable = eco story
A16: CRF-010 | B16: Hand-Painted Terracotta Diya Pair | C16: Crafted In-House | D16: In-house | E16: ='Crafted In-House'!H16 -> 140.33333 | F16: 229 | G16: =IF(F16=0,0,(F16-E16)/F16) -> 0.38719068 | H16: 1 | I16: 3 | J16: Festive boxes | K16: Diwali bestseller
A17: CRF-011 | B17: Custom Ribbon + Brand Tag Finishing Set | C17: Crafted In-House | D17: In-house | E17: ='Crafted In-House'!H17 -> 47 | F17: 89 | G17: =IF(F17=0,0,(F17-E17)/F17) -> 0.47191011 | H17: 1 | I17: 3 | J17: Every box | K17: In brand colours
A18: CRF-012 | B18: Mini Gratitude Journal (Hand-Bound) | C18: Crafted In-House | D18: In-house | E18: ='Crafted In-House'!H18 -> 276.66667 | F18: 449 | G18: =IF(F18=0,0,(F18-E18)/F18) -> 0.38381589 | H18: 1 | I18: 3 | J18: HR, Education | K18: Handmade paper cover
A19: DRINKWARE
A20: DRK-001 | B20: Double-Wall Insulated Steel Bottle 750ml | C20: Drinkware | D20: Vendor | E20: 240 | F20: 449 | G20: =IF(F20=0,0,(F20-E20)/F20) -> 0.46547884 | H20: 25 | I20: 7 | J20: Manufacturing, Tech | K20: Laser engraving
A21: DRK-002 | B21: Ceramic Mug (Matte, Brand Colour) | C21: Drinkware | D21: Vendor | E21: 110 | F21: 249 | G21: =IF(F21=0,0,(F21-E21)/F21) -> 0.55823293 | H21: 50 | I21: 10 | J21: EdTech, HR | K21: Sleeve print
A22: DRK-003 | B22: Glass Sipper with Bamboo Lid | C22: Drinkware | D22: Vendor | E22: 130 | F22: 279 | G22: =IF(F22=0,0,(F22-E22)/F22) -> 0.53405018 | H22: 25 | I22: 7 | J22: Wellness tiers
A23: DRK-004 | B23: Copper Water Bottle (Hammered) | C23: Drinkware | D23: Artisan | E23: 320 | F23: 649 | G23: =IF(F23=0,0,(F23-E23)/F23) -> 0.50693374 | H23: 20 | I23: 12 | J23: Finance, CXO | K23: Ayurveda story
A24: DRK-005 | B24: Cutting Chai Glass Set of 2 + Kettle Mini | C24: Drinkware | D24: Vendor | E24: 260 | F24: 549 | G24: =IF(F24=0,0,(F24-E24)/F24) -> 0.52641166 | H24: 20 | I24: 10 | J24: Fun/team boxes | K24: Chai nostalgia
A25: DRK-006 | B25: Travel French Press 350ml | C25: Drinkware | D25: Vendor | E25: 380 | F25: 749 | G25: =IF(F25=0,0,(F25-E25)/F25) -> 0.49265688 | H25: 15 | I25: 12 | J25: Tech, CS heads
A26: GOURMET
A27: GRM-001 | B27: Artisan Dry Fruit Box 200g (Trail Mix) | C27: Gourmet | D27: Vendor | E27: 180 | F27: 379 | G27: =IF(F27=0,0,(F27-E27)/F27) -> 0.52506596 | H27: 25 | I27: 5 | J27: All industries | K27: 6-mo shelf life
A28: GRM-002 | B28: Single-Estate Assam Tea Tin 100g | C28: Gourmet | D28: Estate direct | E28: 140 | F28: 329 | G28: =IF(F28=0,0,(F28-E28)/F28) -> 0.57446809 | H28: 25 | I28: 10 | J28: Finance, Education | K28: GI-tag story
A29: GRM-003 | B29: Filter Coffee Powder 250g (South Estate) | C29: Gourmet | D29: Estate direct | E29: 160 | F29: 349 | G29: =IF(F29=0,0,(F29-E29)/F29) -> 0.54154728 | H29: 25 | I29: 10 | J29: Tech
A30: GRM-004 | B30: Dark Chocolate Bar 70% (Bean-to-Bar, Indian) | C30: Gourmet | D30: Vendor | E30: 150 | F30: 299 | G30: =IF(F30=0,0,(F30-E30)/F30) -> 0.49832776 | H30: 30 | I30: 7 | J30: All industries | K30: Vegan option
A31: GRM-005 | B31: Millet Cookie Jar 150g | C31: Gourmet | D31: Vendor | E31: 120 | F31: 269 | G31: =IF(F31=0,0,(F31-E31)/F31) -> 0.55390335 | H31: 30 | I31: 7 | J31: Wellness, HR | K31: Healthy angle
A32: GRM-006 | B32: Raw Forest Honey 250g | C32: Gourmet | D32: FPO/SHG | E32: 170 | F32: 349 | G32: =IF(F32=0,0,(F32-E32)/F32) -> 0.51289398 | H32: 25 | I32: 10 | J32: Finance, CXO | K32: Farmer story
A33: GRM-007 | B33: Chai Masala + Saffron Mini Duo | C33: Gourmet | D33: Vendor | E33: 130 | F33: 289 | G33: =IF(F33=0,0,(F33-E33)/F33) -> 0.55017301 | H33: 25 | I33: 7 | J33: Festive
A34: GRM-008 | B34: Gourmet Makhana Duo (2 flavours) | C34: Gourmet | D34: Vendor | E34: 140 | F34: 299 | G34: =IF(F34=0,0,(F34-E34)/F34) -> 0.53177258 | H34: 30 | I34: 7 | J34: Manufacturing teams
A35: DESK & STATIONERY
A36: DSK-001 | B36: A5 Vegan-Leather Notebook (Debossed Logo) | C36: Desk & Stationery | D36: Vendor | E36: 160 | F36: 349 | G36: =IF(F36=0,0,(F36-E36)/F36) -> 0.54154728 | H36: 50 | I36: 10 | J36: All industries
A37: DSK-002 | B37: Handmade-Paper Notebook (Seed Cover) | C37: Desk & Stationery | D37: Artisan | E37: 120 | F37: 279 | G37: =IF(F37=0,0,(F37-E37)/F37) -> 0.56989247 | H37: 30 | I37: 10 | J37: Education, ESG | K37: Plantable cover
A38: DSK-003 | B38: Metal Pen (Gunmetal, Engraved) | C38: Desk & Stationery | D38: Vendor | E38: 90 | F38: 199 | G38: =IF(F38=0,0,(F38-E38)/F38) -> 0.54773869 | H38: 50 | I38: 7 | J38: Finance
A39: DSK-004 | B39: Brass Paperweight (Geometric) | C39: Desk & Stationery | D39: Artisan | E39: 210 | F39: 449 | G39: =IF(F39=0,0,(F39-E39)/F39) -> 0.53229399 | H39: 20 | I39: 14 | J39: Finance, CXO | K39: Moradabad craft
A40: DSK-005 | B40: Desk Plant (Jade/Succulent) in Ceramic Pot | C40: Desk & Stationery | D40: Local nursery | E40: 110 | F40: 269 | G40: =IF(F40=0,0,(F40-E40)/F40) -> 0.59107807 | H40: 20 | I40: 3 | J40: HR, EdTech | K40: Local delivery only
A41: DSK-006 | B41: Wooden Desk Organiser (2-Slot + Phone Dock) | C41: Desk & Stationery | D41: Artisan | E41: 260 | F41: 549 | G41: =IF(F41=0,0,(F41-E41)/F41) -> 0.52641166 | H41: 20 | I41: 14 | J41: Tech, Manufacturing | K41: Channapatna option
...

Sheet Crafted In-House
A1: CRAFTED-BY-ME LINE — Unit Costing
A2: Blue = your inputs. Labor rate below drives all labor costs. Master sheet pulls Total Unit Cost from column H automatically.
A4: Your labor rate (₹/hour): | C4: 250 | D4: ← set this to what your making-time is worth
A6: SKU | B6: Product | C6: Materials (₹) | D6: Labor (mins) | E6: Labor Cost (₹) | F6: Packaging (₹) | G6: Batch/Day (units) | H6: Total Unit Cost (₹) | I6: Selling Price (₹) | J6: Margin % | K6: Best For
A7: CRF-001 | B7: Velvet-Lined Wooden Keepsake Tray (Small) | C7: 210 | D7: 35 | E7: =D7/60*$C$4 -> 145.83333 | F7: 28 | G7: 14 | H7: =C7+E7+F7 -> 383.83333 | I7: 749 | J7: =IF(I7=0,0,(I7-H7)/I7) -> 0.48753894 | K7: CXO gifting, Finance
A8: CRF-002 | B8: Velvet-Lined Wooden Keepsake Tray (Large) | C8: 340 | D8: 50 | E8: =D8/60*$C$4 -> 208.33333 | F8: 35 | G8: 10 | H8: =C8+E8+F8 -> 583.33333 | I8: 1199 | J8: =IF(I8=0,0,(I8-H8)/I8) -> 0.51348346 | K8: CXO / investor boxes
A9: CRF-003 | B9: Hand-Poured Soy Candle 120g (Custom Scent) | C9: 95 | D9: 18 | E9: =D9/60*$C$4 -> 75 | F9: 22 | G9: 27 | H9: =C9+E9+F9 -> 192 | I9: 399 | J9: =IF(I9=0,0,(I9-H9)/I9) -> 0.51879699 | K9: All industries
A10: CRF-004 | B10: Hand-Poured Soy Candle 220g (Amber Jar) | C10: 150 | D10: 22 | E10: =D10/60*$C$4 -> 91.666667 | F10: 25 | G10: 22 | H10: =C10+E10+F10 -> 266.66667 | I10: 599 | J10: =IF(I10=0,0,(I10-H10)/I10) -> 0.55481358 | K10: Premium tiers
A11: CRF-005 | B11: Resin Coaster Set of 2 (Brand Colours) | C11: 85 | D11: 30 | E11: =D11/60*$C$4 -> 125 | F11: 18 | G11: 16 | H11: =C11+E11+F11 -> 228 | I11: 349 | J11: =IF(I11=0,0,(I11-H11)/I11) -> 0.34670487 | K11: Tech, Marketing
A12: CRF-006 | B12: Hand-Lettered Note Card + Wax Seal | C12: 18 | D12: 8 | E12: =D12/60*$C$4 -> 33.333333 | F12: 5 | G12: 60 | H12: =C12+E12+F12 -> 56.333333 | I12: 79 | J12: =IF(I12=0,0,(I12-H12)/I12) -> 0.28691983 | K12: Every box
A13: CRF-007 | B13: Dried-Flower Mini Frame | C13: 70 | D13: 25 | E13: =D13/60*$C$4 -> 104.16667 | F13: 20 | G13: 19 | H13: =C13+E13+F13 -> 194.16667 | I13: 329 | J13: =IF(I13=0,0,(I13-H13)/I13) -> 0.40982776 | K13: HR milestones, EdTech
A14: CRF-008 | B14: Potpourri Sachet in Block-Print Pouch | C14: 40 | D14: 10 | E14: =D14/60*$C$4 -> 41.666667 | F14: 8 | G14: 48 | H14: =C14+E14+F14 -> 89.666667 | I14: 149 | J14: =IF(I14=0,0,(I14-H14)/I14) -> 0.39821029 | K14: Filler / aroma layer
A15: CRF-009 | B15: Hand-Tied Fabric Gift Wrap (Furoshiki Style) | C15: 55 | D15: 12 | E15: =D15/60*$C$4 -> 50 | F15: 0 | G15: 40 | H15: =C15+E15+F15 -> 105 | I15: 199 | J15: =IF(I15=0,0,(I15-H15)/I15) -> 0.47236181 | K15: Premium wrap upgrade
A16: CRF-010 | B16: Hand-Painted Terracotta Diya Pair | C16: 45 | D16: 20 | E16: =D16/60*$C$4 -> 83.333333 | F16: 12 | G16: 24 | H16: =C16+E16+F16 -> 140.33333 | I16: 229 | J16: =IF(I16=0,0,(I16-H16)/I16) -> 0.38719068 | K16: Festive boxes
A17: CRF-011 | B17: Custom Ribbon + Brand Tag Finishing Set | C17: 22 | D17: 6 | E17: =D17/60*$C$4 -> 25 | F17: 0 | G17: 80 | H17: =C17+E17+F17 -> 47 | I17: 89 | J17: =IF(I17=0,0,(I17-H17)/I17) -> 0.47191011 | K17: Every box
A18: CRF-012 | B18: Mini Gratitude Journal (Hand-Bound) | C18: 95 | D18: 40 | E18: =D18/60*$C$4 -> 166.66667 | F18: 15 | G18: 12 | H18: =C18+E18+F18 -> 276.66667 | I18: 449 | J18: =IF(I18=0,0,(I18-H18)/I18) -> 0.38381589 | K18: HR, Education
A20: Assumption: Batch/Day = 8 working hours ÷ labor mins per unit. If your actual crafts differ from this starter list, edit names/materials freely — formulas will follow.

Sheet Industry Boxes
A1: INDUSTRY-SPECIFIC BOX BUILDER
A2: Costs auto-pull from Master Products by SKU. Blue = qty & markup inputs. Change any component SKU and the box re-costs itself.
A4: EDUCATION & EDTECH
A5: Theme: growth, learning, calm focus. Buyers: HR/founders at edtechs, school & university admin, L&D heads.
A7: The First-Bell Box (Essential)
A8: SKU | B8: Component | C8: Qty | D8: Unit Cost (₹) | E8: Line Cost (₹) | F8: Why it's in this box
A9: DSK-002 | B9: Seed-cover handmade notebook | C9: 1 | D9: =IFERROR(INDEX('Master Products'!$E:$E,MATCH($A9,'Master Products'!$A:$A,0)),0) -> 120 | E9: =C9*D9 -> 120 | F9: Plantable = growth metaphor
A10: ECO-004 | B10: Seed-pencil box of 5 | C10: 1 | D10: =IFERROR(INDEX('Master Products'!$E:$E,MATCH($A10,'Master Products'!$A:$A,0)),0) -> 60 | E10: =C10*D10 -> 60 | F10: Signature education item
A11: DRK-002 | B11: Ceramic mug, brand colour | C11: 1 | D11: =IFERROR(INDEX('Master Products'!$E:$E,MATCH($A11,'Master Products'!$A:$A,0)),0) -> 110 | E11: =C11*D11 -> 110 | F11: Daily desk presence
A12: WEL-002 | B12: Herbal tea sampler | C12: 1 | D12: =IFERROR(INDEX('Master Products'!$E:$E,MATCH($A12,'Master Products'!$A:$A,0)),0) -> 90 | E12: =C12*D12 -> 90 | F12: Calm-focus angle
A13: CRF-006 | B13: Hand-lettered note + wax seal | C13: 1 | D13: =IFERROR(INDEX('Master Products'!$E:$E,MATCH($A13,'Master Products'!$A:$A,0)),0) -> 56.333333 | E13: =C13*D13 -> 56.333333 | F13: Personal touch
A14: PKG-001 | B14: Rigid box small + | C14: 1 | D14: =IFERROR(INDEX('Master Products'!$E:$E,MATCH($A14,'Master Products'!$A:$A,0)),0) -> 70 | E14: =C14*D14 -> 70 | F14: —
A15: PKG-004 | B15: Fill + tissue | C15: 1 | D15: =IFERROR(INDEX('Master Products'!$E:$E,MATCH($A15,'Master Products'!$A:$A,0)),0) -> 18 | E15: =C15*D15 -> 18 | F15: —
B16: Box Total Cost | E16: =SUM(E9:E15) -> 524.33333
B17: Markup multiplier (edit) | E17: 1.9
B18: Suggested Selling Price (rounded to ₹49/99) | E18: =ROUND(E16*E17/50,0)*50-1 -> 999
B19: Gross Margin % | E19: =IF(E18=0,0,(E18-E16)/E18) -> 0.47514181
A22: The Educator's Desk (Signature)
A23: SKU | B23: Component | C23: Qty | D23: Unit Cost (₹) | E23: Line Cost (₹) | F23: Why it's in this box
A24: DSK-001 | B24: Vegan-leather notebook | C24: 1 | D24: =IFERROR(INDEX('Master Products'!$E:$E,MATCH($A24,'Master Products'!$A:$A,0)),0) -> 160 | E24: =C24*D24 -> 160 | F24: Professional upgrade
A25: DSK-008 | B25: Brass etched bookmark | C25: 1 | D25: =IFERROR(INDEX('Master Products'!$E:$E,MATCH($A25,'Master Products'!$A:$A,0)),0) -> 70 | E25: =C25*D25 -> 70 | F25: Book-culture nod
A26: CRF-012 | B26: Hand-bound gratitude journal | C26: 1 | D26: =IFERROR(INDEX('Master Products'!$E:$E,MATCH($A26,'Master Products'!$A:$A,0)),0) -> 276.66667 | E26: =C26*D26 -> 276.66667 | F26: Crafted hero item
A27: GRM-002 | B27: Assam estate tea tin | C27: 1 | D27: =IFERROR(INDEX('Master Products'!$E:$E,MATCH($A27,'Master Products'!$A:$A,0)),0) -> 140 | E27: =C27*D27 -> 140 | F27: Staff-room favourite
A28: DSK-005 | B28: Desk succulent in ceramic pot | C28: 1 | D28: =IFERROR(INDEX('Master Products'!$E:$E,MATCH($A28,'Master Products'!$A:$A,0)),0) -> 110 | E28: =C28*D28 -> 110 | F28: Living reminder of growth
A29: CRF-006 | B29: Hand-lettered note + wax seal | C29: 1 | D29: =IFERROR(INDEX('Master Products'!$E:$E,MATCH($A29,'Master Products'!$A:$A,0)),0) -> 56.333333 | E29: =C29*D29 -> 56.333333
A30: PKG-002 | B30: Rigid box medium | C30: 1 | D30: =IFERROR(INDEX('Master Products'!$E:$E,MATCH($A30,'Master Products'!$A:$A,0)),0) -> 105 | E30: =C30*D30 -> 105 | F30: —
A31: PKG-004 | B31: Fill + tissue | C31: 1 | D31: =IFERROR(INDEX('Master Products'!$E:$E,MATCH($A31,'Master Products'!$A:$A,0)),0) -> 18 | E31: =C31*D31 -> 18 | F31: —
B32: Box Total Cost | E32: =SUM(E24:E31) -> 936
B33: Markup multiplier (edit) | E33: 2
B34: Suggested Selling Price (rounded to ₹49/99) | E34: =ROUND(E32*E33/50,0)*50-1 -> 1849
B35: Gross Margin % | E35: =IF(E34=0,0,(E34-E32)/E34) -> 0.49378042
A38: The Learning Leader (Executive)
A39: SKU | B39: Component | C39: Qty | D39: Unit Cost (₹) | E39: Line Cost (₹) | F39: Why it's in this box
A40: CRF-001 | B40: Velvet keepsake tray (small) | C40: 1 | D40: =IFERROR(INDEX('Master Products'!$E:$E,MATCH($A40,'Master Products'!$A:$A,0)),0) -> 383.83333 | E40: =C40*D40 -> 383.83333 | F40: Crafted hero
A41: DSK-004 | B41: Brass paperweight | C41: 1 | D41: =IFERROR(INDEX('Master Products'!$E:$E,MATCH($A41,'Master Products'!$A:$A,0)),0) -> 210 | E41: =C41*D41 -> 210 | F41: Gravitas
A42: GRM-006 | B42: Raw forest honey | C42: 1 | D42: =IFERROR(INDEX('Master Products'!$E:$E,MATCH($A42,'Master Products'!$A:$A,0)),0) -> 170 | E42: =C42*D42 -> 170 | F42: Origin story
A43: GRM-004 | B43: Bean-to-bar dark chocolate | C43: 1 | D43: =IFERROR(INDEX('Master Products'!$E:$E,MATCH($A43,'Master Products'!$A:$A,0)),0) -> 150 | E43: =C43*D43 -> 150
A44: CRF-003 | B44: Soy candle 120g custom scent | C44: 1 | D44: =IFERROR(INDEX('Master Products'!$E:$E,MATCH($A44,'Master Products'!$A:$A,0)),0) -> 192 | E44: =C44*D44 -> 192 | F44: Crafted layer
A45: CRF-006 | B45: Hand-lettered note + wax seal | C45: 1 | D45: =IFERROR(INDEX('Master Products'!$E:$E,MATCH($A45,'Master Products'!$A:$A,0)),0) -> 56.333333 | E45: =C45*D45 -> 56.333333
A46: PKG-003 | B46: Rigid box large + sleeve | C46: 1 | D46: =IFERROR(INDEX('Master Products'!$E:$E,MATCH($A46,'Master Products'!$A:$A,0)),0) -> 150 | E46: =C46*D46 -> 150 | F46: —
...

Sheet Box Summary
A1: ALL BOXES AT A GLANCE
A2: Auto-linked to Industry Boxes sheet — changes flow here instantly.
A4: Industry | B4: Box | C4: Total Cost (₹) | D4: Selling Price (₹) | E4: Gross Margin %
A5: Education & Edtech | B5: The First-Bell Box (Essential) | C5: ='Industry Boxes'!E16 -> 524.33333 | D5: ='Industry Boxes'!E18 -> 999 | E5: ='Industry Boxes'!E19 -> 0.47514181
A6: Education & Edtech | B6: The Educator's Desk (Signature) | C6: ='Industry Boxes'!E32 -> 936 | D6: ='Industry Boxes'!E34 -> 1849 | E6: ='Industry Boxes'!E35 -> 0.49378042
A7: Education & Edtech | B7: The Learning Leader (Executive) | C7: ='Industry Boxes'!E48 -> 1330.1667 | D7: ='Industry Boxes'!E50 -> 2799 | E7: ='Industry Boxes'!E51 -> 0.52477075
A8: Finance & Bfsi | B8: The Ledger Box (Essential — policy-safe) | C8: ='Industry Boxes'!E66 -> 454.33333 | D8: ='Industry Boxes'!E68 -> 849 | E8: ='Industry Boxes'!E69 -> 0.46486062
A9: Finance & Bfsi | B9: The Portfolio Box (Signature) | C9: ='Industry Boxes'!E81 -> 1039.3333 | D9: ='Industry Boxes'!E83 -> 2099 | E9: ='Industry Boxes'!E84 -> 0.50484358
A10: Finance & Bfsi | B10: The Corner Office (Executive) | C10: ='Industry Boxes'!E98 -> 1599.3333 | D10: ='Industry Boxes'!E100 -> 3449 | E10: ='Industry Boxes'!E101 -> 0.53629071
A11: Manufacturing & Industrial | B11: The Floor Crew Box (Essential — bulk hero) | C11: ='Industry Boxes'!E115 -> 501 | D11: ='Industry Boxes'!E117 -> 949 | E11: ='Industry Boxes'!E118 -> 0.47207587
A12: Manufacturing & Industrial | B12: The Foreman's Box (Signature) | C12: ='Industry Boxes'!E130 -> 1087.3333 | D12: ='Industry Boxes'!E132 -> 2099 | E12: ='Industry Boxes'!E133 -> 0.48197554
A13: Manufacturing & Industrial | B13: The Plant Head Box (Executive) | C13: ='Industry Boxes'!E145 -> 1308.1667 | D13: ='Industry Boxes'!E147 -> 2699 | E13: ='Industry Boxes'!E148 -> 0.51531431
A14: Tech & Saas | B14: The Onboard Kit (Essential) | C14: ='Industry Boxes'!E163 -> 463 | D14: ='Industry Boxes'!E165 -> 899 | E14: ='Industry Boxes'!E166 -> 0.48498331
A15: Tech & Saas | B15: The Deep Work Box (Signature) | C15: ='Industry Boxes'!E178 -> 907.33333 | D15: ='Industry Boxes'!E180 -> 1799 | E15: ='Industry Boxes'!E181 -> 0.49564573
A16: Tech & Saas | B16: The Founder Box (Executive / ABM) | C16: ='Industry Boxes'!E194 -> 1510.1667 | D16: ='Industry Boxes'!E196 -> 3149 | E16: ='Industry Boxes'!E197 -> 0.52042977
